<?xml version="1.0" encoding="utf-8"?>
<!-- This URDF was automatically created by SolidWorks to URDF Exporter! Originally created by Stephen Brawner (brawner@gmail.com) 
     Commit Version: 1.6.0-4-g7f85cfe  Build Version: 1.6.7995.38578
     For more information, please see http://wiki.ros.org/sw_urdf_exporter -->
<robot
  name="agvcar">
  <link
    name="front_base">
    <visual>
      <origin
        xyz="0 0 0"
        rpy="0 0 0" />
      <geometry>
        <box size="0.01 0.01 0.01"/>
      </geometry>
    </visual>
  </link>
  <link
    name="base_link">
    <inertial>
      <origin
        xyz="0.0535596635670063 -7.75930973195837E-06 0.0864450067600846"
        rpy="0 0 0" />
      <mass
        value="13.4285294805367" />
      <inertia
        ixx="0.0493474568714098"
        ixy="-6.5377130573348E-11"
        ixz="1.55124810899379E-06"
        iyy="0.0974844673307596"
        iyz="-1.85077943424468E-09"
        izz="0.133169285413625" />
    </inertial>
    <visual>
      <origin
        xyz="0 0 0"
        rpy="0 0 0" />
      <geometry>
        <mesh
          filename="package://agvcar/meshes/base_link.STL" />
      </geometry>
      <material
        name="">
        <color
          rgba="0.647058823529412 0.517647058823529 0 1" />
      </material>
    </visual>
    <collision>
      <origin
        xyz="0 0 0"
        rpy="0 0 0" />
      <geometry>
        <mesh
          filename="package://agvcar/meshes/base_link.STL" />
      </geometry>
    </collision>
  </link>
  <joint
    name="frontbase"
    type="fixed">
    <origin
      xyz="0 0 0.02"
      rpy="0 0 0" />
    <parent
      link="front_base" />
    <child
      link="base_link" />
  </joint>
  <link
    name="zql">
    <inertial>
      <origin
        xyz="0 0.00655993549543088 -2.08166817117217E-17"
        rpy="0 0 0" />
      <mass
        value="0.24686785868356" />
      <inertia
        ixx="0.000186555687353195"
        ixy="5.54971750626698E-19"
        ixz="1.1336124277419E-20"
        iyy="0.000332239900624819"
        iyz="-2.1205858328098E-19"
        izz="0.000186555687353195" />
    </inertial>
    <visual>
      <origin
        xyz="0 0 0"
        rpy="0 0 0" />
      <geometry>
        <mesh
          filename="package://agvcar/meshes/zql.STL" />
      </geometry>
      <material
        name="">
        <color
          rgba="0.298039215686275 0.298039215686275 0.298039215686275 1" />
      </material>
    </visual>
    <collision>
      <origin
        xyz="0 0 0"
        rpy="0 0 0" />
      <geometry>
        <mesh
          filename="package://agvcar/meshes/zql.STL" />
      </geometry>
    </collision>
  </link>
  <joint
    name="zq"
    type="continuous">
    <origin
      xyz="0.134 0.11846 0.0358000000000002"
      rpy="0 0 0" />
    <parent
      link="base_link" />
    <child
      link="zql" />
    <axis
      xyz="0 1 0" />
  </joint>
  <link
    name="yql">
    <inertial>
      <origin
        xyz="1.11022302462516E-16 -0.00655993549543132 0"
        rpy="0 0 0" />
      <mass
        value="0.24686785868356" />
      <inertia
        ixx="0.000186555687353195"
        ixy="5.21507883374648E-19"
        ixz="6.6845016754145E-21"
        iyy="0.000332239900624819"
        iyz="-2.06921789956204E-19"
        izz="0.000186555687353195" />
    </inertial>
    <visual>
      <origin
        xyz="0 0 0"
        rpy="0 0 0" />
      <geometry>
        <mesh
          filename="package://agvcar/meshes/yql.STL" />
      </geometry>
      <material
        name="">
        <color
          rgba="0.298039215686275 0.298039215686275 0.298039215686275 1" />
      </material>
    </visual>
    <collision>
      <origin
        xyz="0 0 0"
        rpy="0 0 0" />
      <geometry>
        <mesh
          filename="package://agvcar/meshes/yql.STL" />
      </geometry>
    </collision>
  </link>
  <joint
    name="yq"
    type="continuous">
    <origin
      xyz="0.133999999999999 -0.11846 0.0358000000000006"
      rpy="0 0 0" />
    <parent
      link="base_link" />
    <child
      link="yql" />
    <axis
      xyz="0 -1 0" />
  </joint>
  <link
    name="zhl">
    <inertial>
      <origin
        xyz="-6.93889390390723E-17 0.00655993549543088 -6.93889390390723E-18"
        rpy="0 0 0" />
      <mass
        value="0.24686785868356" />
      <inertia
        ixx="0.000186555687353195"
        ixy="5.09181411447997E-19"
        ixz="-1.25607927469927E-20"
        iyy="0.000332239900624819"
        iyz="-2.08843859917431E-19"
        izz="0.000186555687353195" />
    </inertial>
    <visual>
      <origin
        xyz="0 0 0"
        rpy="0 0 0" />
      <geometry>
        <mesh
          filename="package://agvcar/meshes/zhl.STL" />
      </geometry>
      <material
        name="">
        <color
          rgba="0.298039215686275 0.298039215686275 0.298039215686275 1" />
      </material>
    </visual>
    <collision>
      <origin
        xyz="0 0 0"
        rpy="0 0 0" />
      <geometry>
        <mesh
          filename="package://agvcar/meshes/zhl.STL" />
      </geometry>
    </collision>
  </link>
  <joint
    name="zh"
    type="continuous">
    <origin
      xyz="-0.134 0.118460000000001 0.0357999999999995"
      rpy="0 0 0" />
    <parent
      link="base_link" />
    <child
      link="zhl" />
    <axis
      xyz="0 1 0" />
  </joint>
  <link
    name="yhl">
    <inertial>
      <origin
        xyz="6.93889390390723E-17 -0.00655993549543088 1.38777878078145E-17"
        rpy="0 0 0" />
      <mass
        value="0.24686785868356" />
      <inertia
        ixx="0.000186555687353195"
        ixy="5.22839018577619E-19"
        ixz="2.81461989764704E-20"
        iyy="0.000332239900624819"
        iyz="-2.0295506492961E-19"
        izz="0.000186555687353195" />
    </inertial>
    <visual>
      <origin
        xyz="0 0 0"
        rpy="0 0 0" />
      <geometry>
        <mesh
          filename="package://agvcar/meshes/yhl.STL" />
      </geometry>
      <material
        name="">
        <color
          rgba="0.298039215686275 0.298039215686275 0.298039215686275 1" />
      </material>
    </visual>
    <collision>
      <origin
        xyz="0 0 0"
        rpy="0 0 0" />
      <geometry>
        <mesh
          filename="package://agvcar/meshes/yhl.STL" />
      </geometry>
    </collision>
  </link>
  <joint
    name="yh"
    type="continuous">
    <origin
      xyz="-0.134000000000001 -0.118459999999999 0.0357999999999998"
      rpy="0 0 0" />
    <parent
      link="base_link" />
    <child
      link="yhl" />
    <axis
      xyz="0 -1 0" />
  </joint>
  <link
    name="ladar">
    <inertial>
      <origin
        xyz="1.00438546368764E-11 -5.09414732619007E-12 0.0222462705397482"
        rpy="0 0 0" />
      <mass
        value="0.180802376452422" />
      <inertia
        ixx="8.86105371612917E-05"
        ixy="1.49899275371219E-14"
        ixz="3.75499657275673E-14"
        iyy="8.86105368846044E-05"
        iyz="-1.35257771200435E-14"
        izz="0.000116614517328158" />
    </inertial>
    <visual>
      <origin
        xyz="0 0 0"
        rpy="0 0 0" />
      <geometry>
        <mesh
          filename="package://agvcar/meshes/ladar.STL" />
      </geometry>
      <material
        name="">
        <color
          rgba="0.223529411764706 0.223529411764706 0.223529411764706 1" />
      </material>
    </visual>
    <collision>
      <origin
        xyz="0 0 0"
        rpy="0 0 0" />
      <geometry>
        <mesh
          filename="package://agvcar/meshes/ladar.STL" />
      </geometry>
    </collision>
  </link>
  <joint
    name="ladar_body"
    type="fixed">
    <origin
      xyz="0.141469568517405 0 0.160500000000001"
      rpy="0 0 0" />
    <parent
      link="base_link" />
    <child
      link="ladar" />
    <axis
      xyz="0 0 0" />
  </joint>
  <link
    name="camera">
    <inertial>
      <origin
        xyz="0.0114440208259819 0.0017049811987826 -0.000136108231652915"
        rpy="0 0 0" />
      <mass
        value="0.107910427285576" />
      <inertia
        ixx="7.12550269124956E-05"
        ixy="-1.78474723509806E-08"
        ixz="-4.9297800794627E-08"
        iyy="7.71002128129154E-06"
        iyz="-2.48245266673343E-10"
        izz="7.02567377723332E-05" />
    </inertial>
    <visual>
      <origin
        xyz="0 0 0"
        rpy="0 0 0" />
      <geometry>
        <mesh
          filename="package://agvcar/meshes/camera.STL" />
      </geometry>
      <material
        name="">
        <color
          rgba="0.898039215686275 0.917647058823529 0.929411764705882 1" />
      </material>
    </visual>
    <collision>
      <origin
        xyz="0 0 0"
        rpy="0 0 0" />
      <geometry>
        <mesh
          filename="package://agvcar/meshes/camera.STL" />
      </geometry>
    </collision>
  </link>
  <joint
    name="camera_body"
    type="fixed">
    <origin
      xyz="-0.25461593319414 -0.00206095974626663 0.162274122782275"
      rpy="0 0 0" />
    <parent
      link="base_link" />
    <child
      link="camera" />
    <axis
      xyz="0 0 0" />
  </joint>
</robot>
